Workbook

Sheet Korting
A1: Invullen SVP
A2: Kortingspercentage 2026 | B2: 0 | D2: Vul aub rechts uw korting in en het btw tarief om op de sheets uw inkoopprijs te berekenen!
A3: BTW tarief | B3: 0.21

Sheet 70
A1: Square 70
A2: Motor (Screenjob LS40) Draaistangbediening | B2: H B | C2: 100 | D2: 120 | E2: 140 | F2: 160 | G2: 180 | H2: 200 | I2: 220 | J2: 240
B3: 100 | C3: =(('70 (2)'!C3/(1+Korting!$B$3)*(1-Korting!$B$2)*Prijsmutaties!$B$9)) -> 310.33112 | D3: =(('70 (2)'!D3/(1+Korting!$B$3)*(1-Korting!$B$2)*Prijsmutaties!$B$9)) -> 328.63974 | E3: =(('70 (2)'!E3/(1+Korting!$B$3)*(1-Korting!$B$2)*Prijsmutaties!$B$9)) -> 352.44095 | F3: =(('70 (2)'!F3/(1+Korting!$B$3)*(1-Korting!$B$2)*Prijsmutaties!$B$9)) -> 372.58043 | G3: =(('70 (2)'!G3/(1+Korting!$B$3)*(1-Korting!$B$2)*Prijsmutaties!$B$9)) -> 392.71991 | H3: =(('70 (2)'!H3/(1+Korting!$B$3)*(1-Korting!$B$2)*Prijsmutaties!$B$9)) -> 409.19767 | I3: =(('70 (2)'!I3/(1+Korting!$B$3)*(1-Korting!$B$2)*Prijsmutaties!$B$9)) -> 435.74517 | J3: =(('70 (2)'!J3/(1+Korting!$B$3)*(1-Korting!$B$2)*Prijsmutaties!$B$9)) -> 455.52672 | K3: 100
B4: 120 | C4: =(('70 (2)'!C4/(1+Korting!$B$3)*(1-Korting!$B$2)*Prijsmutaties!$B$9)) -> 318.57 | D4: =(('70 (2)'!D4/(1+Korting!$B$3)*(1-Korting!$B$2)*Prijsmutaties!$B$9)) -> 338.70948 | E4: =(('70 (2)'!E4/(1+Korting!$B$3)*(1-Korting!$B$2)*Prijsmutaties!$B$9)) -> 360.67983 | F4: =(('70 (2)'!F4/(1+Korting!$B$3)*(1-Korting!$B$2)*Prijsmutaties!$B$9)) -> 378.98845 | G4: =(('70 (2)'!G4/(1+Korting!$B$3)*(1-Korting!$B$2)*Prijsmutaties!$B$9)) -> 399.12793 | H4: =(('70 (2)'!H4/(1+Korting!$B$3)*(1-Korting!$B$2)*Prijsmutaties!$B$9)) -> 415.60569 | I4: =(('70 (2)'!I4/(1+Korting!$B$3)*(1-Korting!$B$2)*Prijsmutaties!$B$9)) -> 445.81492 | J4: =(('70 (2)'!J4/(1+Korting!$B$3)*(1-Korting!$B$2)*Prijsmutaties!$B$9)) -> 463.2969 | K4: 120
B5: 140 | C5: =(('70 (2)'!C5/(1+Korting!$B$3)*(1-Korting!$B$2)*Prijsmutaties!$B$9)) -> 328.63974 | D5: =(('70 (2)'!D5/(1+Korting!$B$3)*(1-Korting!$B$2)*Prijsmutaties!$B$9)) -> 348.77923 | E5: =(('70 (2)'!E5/(1+Korting!$B$3)*(1-Korting!$B$2)*Prijsmutaties!$B$9)) -> 368.91871 | F5: =(('70 (2)'!F5/(1+Korting!$B$3)*(1-Korting!$B$2)*Prijsmutaties!$B$9)) -> 385.39647 | G5: =(('70 (2)'!G5/(1+Korting!$B$3)*(1-Korting!$B$2)*Prijsmutaties!$B$9)) -> 405.53595 | H5: =(('70 (2)'!H5/(1+Korting!$B$3)*(1-Korting!$B$2)*Prijsmutaties!$B$9)) -> 432.99888 | I5: =(('70 (2)'!I5/(1+Korting!$B$3)*(1-Korting!$B$2)*Prijsmutaties!$B$9)) -> 451.3075 | J5: =(('70 (2)'!J5/(1+Korting!$B$3)*(1-Korting!$B$2)*Prijsmutaties!$B$9)) -> 472.03835 | K5: 140
B6: 160 | C6: =(('70 (2)'!C6/(1+Korting!$B$3)*(1-Korting!$B$2)*Prijsmutaties!$B$9)) -> 342.37121 | D6: =(('70 (2)'!D6/(1+Korting!$B$3)*(1-Korting!$B$2)*Prijsmutaties!$B$9)) -> 362.51069 | E6: =(('70 (2)'!E6/(1+Korting!$B$3)*(1-Korting!$B$2)*Prijsmutaties!$B$9)) -> 385.39647 | F6: =(('70 (2)'!F6/(1+Korting!$B$3)*(1-Korting!$B$2)*Prijsmutaties!$B$9)) -> 407.36681 | G6: =(('70 (2)'!G6/(1+Korting!$B$3)*(1-Korting!$B$2)*Prijsmutaties!$B$9)) -> 435.74517 | H6: =(('70 (2)'!H6/(1+Korting!$B$3)*(1-Korting!$B$2)*Prijsmutaties!$B$9)) -> 455.88466 | I6: =(('70 (2)'!I6/(1+Korting!$B$3)*(1-Korting!$B$2)*Prijsmutaties!$B$9)) -> 476.02414 | J6: =(('70 (2)'!J6/(1+Korting!$B$3)*(1-Korting!$B$2)*Prijsmutaties!$B$9)) -> 500.20525 | K6: 160
B7: 180 | C7: =(('70 (2)'!C7/(1+Korting!$B$3)*(1-Korting!$B$2)*Prijsmutaties!$B$9)) -> 355.18724 | D7: =(('70 (2)'!D7/(1+Korting!$B$3)*(1-Korting!$B$2)*Prijsmutaties!$B$9)) -> 380.81931 | E7: =(('70 (2)'!E7/(1+Korting!$B$3)*(1-Korting!$B$2)*Prijsmutaties!$B$9)) -> 402.78966 | F7: =(('70 (2)'!F7/(1+Korting!$B$3)*(1-Korting!$B$2)*Prijsmutaties!$B$9)) -> 432.99888 | G7: =(('70 (2)'!G7/(1+Korting!$B$3)*(1-Korting!$B$2)*Prijsmutaties!$B$9)) -> 455.88466 | H7: =(('70 (2)'!H7/(1+Korting!$B$3)*(1-Korting!$B$2)*Prijsmutaties!$B$9)) -> 476.02414 | I7: =(('70 (2)'!I7/(1+Korting!$B$3)*(1-Korting!$B$2)*Prijsmutaties!$B$9)) -> 499.82535 | J7: =(('70 (2)'!J7/(1+Korting!$B$3)*(1-Korting!$B$2)*Prijsmutaties!$B$9)) -> 528.37215 | K7: 180
B8: 200 | C8: =(('70 (2)'!C8/(1+Korting!$B$3)*(1-Korting!$B$2)*Prijsmutaties!$B$9)) -> 372.58043 | D8: =(('70 (2)'!D8/(1+Korting!$B$3)*(1-Korting!$B$2)*Prijsmutaties!$B$9)) -> 395.46621 | E8: =(('70 (2)'!E8/(1+Korting!$B$3)*(1-Korting!$B$2)*Prijsmutaties!$B$9)) -> 415.60569 | F8: =(('70 (2)'!F8/(1+Korting!$B$3)*(1-Korting!$B$2)*Prijsmutaties!$B$9)) -> 449.47664 | G8: =(('70 (2)'!G8/(1+Korting!$B$3)*(1-Korting!$B$2)*Prijsmutaties!$B$9)) -> 471.44698 | H8: =(('70 (2)'!H8/(1+Korting!$B$3)*(1-Korting!$B$2)*Prijsmutaties!$B$9)) -> 497.99448 | I8: =(('70 (2)'!I8/(1+Korting!$B$3)*(1-Korting!$B$2)*Prijsmutaties!$B$9)) -> 525.45742 | J8: =(('70 (2)'!J8/(1+Korting!$B$3)*(1-Korting!$B$2)*Prijsmutaties!$B$9)) -> 543.91251 | K8: 200
B9: 220 | C9: =(('70 (2)'!C9/(1+Korting!$B$3)*(1-Korting!$B$2)*Prijsmutaties!$B$9)) -> 395.46621 | D9: =(('70 (2)'!D9/(1+Korting!$B$3)*(1-Korting!$B$2)*Prijsmutaties!$B$9)) -> 427.50629 | E9: =(('70 (2)'!E9/(1+Korting!$B$3)*(1-Korting!$B$2)*Prijsmutaties!$B$9)) -> 455.88466 | F9: =(('70 (2)'!F9/(1+Korting!$B$3)*(1-Korting!$B$2)*Prijsmutaties!$B$9)) -> 481.51673 | G9: =(('70 (2)'!G9/(1+Korting!$B$3)*(1-Korting!$B$2)*Prijsmutaties!$B$9)) -> 509.89509 | H9: =(('70 (2)'!H9/(1+Korting!$B$3)*(1-Korting!$B$2)*Prijsmutaties!$B$9)) -> 535.52716 | I9: =(('70 (2)'!I9/(1+Korting!$B$3)*(1-Korting!$B$2)*Prijsmutaties!$B$9)) -> 570.31354 | K9: 220
B10: 240 | C10: =(('70 (2)'!C10/(1+Korting!$B$3)*(1-Korting!$B$2)*Prijsmutaties!$B$9)) -> 399.12793 | D10: =(('70 (2)'!D10/(1+Korting!$B$3)*(1-Korting!$B$2)*Prijsmutaties!$B$9)) -> 435.74517 | E10: =(('70 (2)'!E10/(1+Korting!$B$3)*(1-Korting!$B$2)*Prijsmutaties!$B$9)) -> 463.2081 | F10: =(('70 (2)'!F10/(1+Korting!$B$3)*(1-Korting!$B$2)*Prijsmutaties!$B$9)) -> 489.7556 | G10: =(('70 (2)'!G10/(1+Korting!$B$3)*(1-Korting!$B$2)*Prijsmutaties!$B$9)) -> 519.96483 | H10: =(('70 (2)'!H10/(1+Korting!$B$3)*(1-Korting!$B$2)*Prijsmutaties!$B$9)) -> 543.76604 | K10: 240
B12: H B | C12: 100 | D12: 120 | E12: 140 | F12: 160 | G12: 180 | H12: 200 | I12: 220 | J12: 240
B13: 100 | C13: =(('70 (2)'!C13/(1+Korting!$B$3)*(1-Korting!$B$2)*Prijsmutaties!$B$9)) -> 505.31793 | D13: =(('70 (2)'!D13/(1+Korting!$B$3)*(1-Korting!$B$2)*Prijsmutaties!$B$9)) -> 521.79569 | E13: =(('70 (2)'!E13/(1+Korting!$B$3)*(1-Korting!$B$2)*Prijsmutaties!$B$9)) -> 543.76604 | F13: =(('70 (2)'!F13/(1+Korting!$B$3)*(1-Korting!$B$2)*Prijsmutaties!$B$9)) -> 568.48267 | G13: =(('70 (2)'!G13/(1+Korting!$B$3)*(1-Korting!$B$2)*Prijsmutaties!$B$9)) -> 588.62216 | H13: =(('70 (2)'!H13/(1+Korting!$B$3)*(1-Korting!$B$2)*Prijsmutaties!$B$9)) -> 606.01535 | I13: =(('70 (2)'!I13/(1+Korting!$B$3)*(1-Korting!$B$2)*Prijsmutaties!$B$9)) -> 628.90112 | J13: =(('70 (2)'!J13/(1+Korting!$B$3)*(1-Korting!$B$2)*Prijsmutaties!$B$9)) -> 648.80992 | K13: 100
B14: 120 | C14: =(('70 (2)'!C14/(1+Korting!$B$3)*(1-Korting!$B$2)*Prijsmutaties!$B$9)) -> 513.55681 | D14: =(('70 (2)'!D14/(1+Korting!$B$3)*(1-Korting!$B$2)*Prijsmutaties!$B$9)) -> 531.86543 | E14: =(('70 (2)'!E14/(1+Korting!$B$3)*(1-Korting!$B$2)*Prijsmutaties!$B$9)) -> 552.00492 | F14: =(('70 (2)'!F14/(1+Korting!$B$3)*(1-Korting!$B$2)*Prijsmutaties!$B$9)) -> 575.80612 | G14: =(('70 (2)'!G14/(1+Korting!$B$3)*(1-Korting!$B$2)*Prijsmutaties!$B$9)) -> 594.11474 | H14: =(('70 (2)'!H14/(1+Korting!$B$3)*(1-Korting!$B$2)*Prijsmutaties!$B$9)) -> 614.25423 | I14: =(('70 (2)'!I14/(1+Korting!$B$3)*(1-Korting!$B$2)*Prijsmutaties!$B$9)) -> 634.39371 | J14: =(('70 (2)'!J14/(1+Korting!$B$3)*(1-Korting!$B$2)*Prijsmutaties!$B$9)) -> 654.63755 | K14: 120
B15: 140 | C15: =(('70 (2)'!C15/(1+Korting!$B$3)*(1-Korting!$B$2)*Prijsmutaties!$B$9)) -> 521.79569 | D15: =(('70 (2)'!D15/(1+Korting!$B$3)*(1-Korting!$B$2)*Prijsmutaties!$B$9)) -> 538.27345 | E15: =(('70 (2)'!E15/(1+Korting!$B$3)*(1-Korting!$B$2)*Prijsmutaties!$B$9)) -> 560.24379 | F15: =(('70 (2)'!F15/(1+Korting!$B$3)*(1-Korting!$B$2)*Prijsmutaties!$B$9)) -> 580.38328 | G15: =(('70 (2)'!G15/(1+Korting!$B$3)*(1-Korting!$B$2)*Prijsmutaties!$B$9)) -> 598.6919 | H15: =(('70 (2)'!H15/(1+Korting!$B$3)*(1-Korting!$B$2)*Prijsmutaties!$B$9)) -> 626.15483 | I15: =(('70 (2)'!I15/(1+Korting!$B$3)*(1-Korting!$B$2)*Prijsmutaties!$B$9)) -> 642.63259 | J15: =(('70 (2)'!J15/(1+Korting!$B$3)*(1-Korting!$B$2)*Prijsmutaties!$B$9)) -> 667.26409 | K15: 140
B16: 160 | C16: =(('70 (2)'!C16/(1+Korting!$B$3)*(1-Korting!$B$2)*Prijsmutaties!$B$9)) -> 533.69629 | D16: =(('70 (2)'!D16/(1+Korting!$B$3)*(1-Korting!$B$2)*Prijsmutaties!$B$9)) -> 555.66664 | E16: =(('70 (2)'!E16/(1+Korting!$B$3)*(1-Korting!$B$2)*Prijsmutaties!$B$9)) -> 580.38328 | F16: =(('70 (2)'!F16/(1+Korting!$B$3)*(1-Korting!$B$2)*Prijsmutaties!$B$9)) -> 602.35362 | G16: =(('70 (2)'!G16/(1+Korting!$B$3)*(1-Korting!$B$2)*Prijsmutaties!$B$9)) -> 628.90112 | H16: =(('70 (2)'!H16/(1+Korting!$B$3)*(1-Korting!$B$2)*Prijsmutaties!$B$9)) -> 649.04061 | I16: =(('70 (2)'!I16/(1+Korting!$B$3)*(1-Korting!$B$2)*Prijsmutaties!$B$9)) -> 671.01095 | J16: =(('70 (2)'!J16/(1+Korting!$B$3)*(1-Korting!$B$2)*Prijsmutaties!$B$9)) -> 690.57463 | K16: 160
B17: 180 | C17: =(('70 (2)'!C17/(1+Korting!$B$3)*(1-Korting!$B$2)*Prijsmutaties!$B$9)) -> 545.5969 | D17: =(('70 (2)'!D17/(1+Korting!$B$3)*(1-Korting!$B$2)*Prijsmutaties!$B$9)) -> 578.55242 | E17: =(('70 (2)'!E17/(1+Korting!$B$3)*(1-Korting!$B$2)*Prijsmutaties!$B$9)) -> 595.94561 | F17: =(('70 (2)'!F17/(1+Korting!$B$3)*(1-Korting!$B$2)*Prijsmutaties!$B$9)) -> 626.15483 | G17: =(('70 (2)'!G17/(1+Korting!$B$3)*(1-Korting!$B$2)*Prijsmutaties!$B$9)) -> 649.04061 | H17: =(('70 (2)'!H17/(1+Korting!$B$3)*(1-Korting!$B$2)*Prijsmutaties!$B$9)) -> 671.01095 | I17: =(('70 (2)'!I17/(1+Korting!$B$3)*(1-Korting!$B$2)*Prijsmutaties!$B$9)) -> 691.15043 | J17: =(('70 (2)'!J17/(1+Korting!$B$3)*(1-Korting!$B$2)*Prijsmutaties!$B$9)) -> 725.54043 | K17: 180
B18: 200 | C18: =(('70 (2)'!C18/(1+Korting!$B$3)*(1-Korting!$B$2)*Prijsmutaties!$B$9)) -> 568.48267 | D18: =(('70 (2)'!D18/(1+Korting!$B$3)*(1-Korting!$B$2)*Prijsmutaties!$B$9)) -> 590.45302 | E18: =(('70 (2)'!E18/(1+Korting!$B$3)*(1-Korting!$B$2)*Prijsmutaties!$B$9)) -> 614.25423 | F18: =(('70 (2)'!F18/(1+Korting!$B$3)*(1-Korting!$B$2)*Prijsmutaties!$B$9)) -> 638.97086 | G18: =(('70 (2)'!G18/(1+Korting!$B$3)*(1-Korting!$B$2)*Prijsmutaties!$B$9)) -> 666.4338 | H18: =(('70 (2)'!H18/(1+Korting!$B$3)*(1-Korting!$B$2)*Prijsmutaties!$B$9)) -> 689.31957 | I18: =(('70 (2)'!I18/(1+Korting!$B$3)*(1-Korting!$B$2)*Prijsmutaties!$B$9)) -> 723.19052 | J18: =(('70 (2)'!J18/(1+Korting!$B$3)*(1-Korting!$B$2)*Prijsmutaties!$B$9)) -> 741.08079 | K18: 200
C20: Meerprijs Trend / RAL kleuren
B21: B | C21: 100 | D21: 120 | E21: 140 | F21: 160 | G21: 180 | H21: 200 | I21: 220 | J21: 240
B22: RAL | C22: =(('70 (2)'!C22/(1+Korting!$B$3)*(1-Korting!$B$2)*Prijsmutaties!$B$9)) -> 198.13956 | D22: =(('70 (2)'!D22/(1+Korting!$B$3)*(1-Korting!$B$2)*Prijsmutaties!$B$9)) -> 198.13956 | E22: =(('70 (2)'!E22/(1+Korting!$B$3)*(1-Korting!$B$2)*Prijsmutaties!$B$9)) -> 198.13956 | F22: =(('70 (2)'!F22/(1+Korting!$B$3)*(1-Korting!$B$2)*Prijsmutaties!$B$9)) -> 198.13956 | G22: =(('70 (2)'!G22/(1+Korting!$B$3)*(1-Korting!$B$2)*Prijsmutaties!$B$9)) -> 198.13956 | H22: =(('70 (2)'!H22/(1+Korting!$B$3)*(1-Korting!$B$2)*Prijsmutaties!$B$9)) -> 254.47335 | I22: =(('70 (2)'!I22/(1+Korting!$B$3)*(1-Korting!$B$2)*Prijsmutaties!$B$9)) -> 254.47335 | J22: =(('70 (2)'!J22/(1+Korting!$B$3)*(1-Korting!$B$2)*Prijsmutaties!$B$9)) -> 254.47335
B23: Trend | C23: =(('70 (2)'!C23/(1+Korting!$B$3)*(1-Korting!$B$2)*Prijsmutaties!$B$9)) -> 99.069778 | D23: =(('70 (2)'!D23/(1+Korting!$B$3)*(1-Korting!$B$2)*Prijsmutaties!$B$9)) -> 99.069778 | E23: =(('70 (2)'!E23/(1+Korting!$B$3)*(1-Korting!$B$2)*Prijsmutaties!$B$9)) -> 99.069778 | F23: =(('70 (2)'!F23/(1+Korting!$B$3)*(1-Korting!$B$2)*Prijsmutaties!$B$9)) -> 99.069778 | G23: =(('70 (2)'!G23/(1+Korting!$B$3)*(1-Korting!$B$2)*Prijsmutaties!$B$9)) -> 99.069778 | H23: =(('70 (2)'!H23/(1+Korting!$B$3)*(1-Korting!$B$2)*Prijsmutaties!$B$9)) -> 127.23668 | I23: =(('70 (2)'!I23/(1+Korting!$B$3)*(1-Korting!$B$2)*Prijsmutaties!$B$9)) -> 127.23668 | J23: =(('70 (2)'!J23/(1+Korting!$B$3)*(1-Korting!$B$2)*Prijsmutaties!$B$9)) -> 127.23668
A25: Veelgekozen opties
A27: Sunea io 40 16 rpm (meerprijs t.o.v. motor) | H27: =(('70 (2)'!H27/(1+Korting!$B$3)*(1-Korting!$B$2)*Prijsmutaties!$G$9)) -> 169.45388
A28: Situo 1 io handzender | H28: =(('70 (2)'!H28/(1+Korting!$B$3)*(1-Korting!$B$2)*Prijsmutaties!$G$9)) -> 63.094529
A29: Sunfix systeem draaistangbediening | H29: =(('70 (2)'!H29/(1+Korting!$B$3)*(1-Korting!$B$2)*Prijsmutaties!$G$9)) -> 55.883726
A30: Sunfix elektrisch inclusief Sunfix schakelaar | H30: =(('70 (2)'!H30/(1+Korting!$B$3)*(1-Korting!$B$2)*Prijsmutaties!$G$9)) -> 197.39574
A31: Minderprijs bandbediening (t.o.v. tabel draaistangbediening) -/-* | H31: =(('70 (2)'!H31/(1+Korting!$B$3)*(1-Korting!$B$2)*Prijsmutaties!$G$9)) -> -51.376974
B32: * Max. H = 200 cm

Sheet 85&100 (2)
A1: Square 85/100 Carré 85/100 (alleen elektrisch)
C2: H B | D2: 100 | E2: 120 | F2: 140 | G2: 160 | H2: 180 | I2: 200 | J2: 220 | K2: 240 | L2: 260 | M2: 280 | O2: 300 | P2: 320 | Q2: 340 | R2: 360 | S2: 380 | T2: 400
C3: 100 | D3: 360.98021 | E3: 388.31291 | F3: 409.04807 | G3: 440.1508 | H3: 464.65598 | I3: 487.27615 | J3: 514.60886 | K3: 540.99906 | L3: 559.8492 | M3: 591 | O3: 613.5721 | P3: 637.13478 | Q3: 668.23751 | R3: 688.97267 | S3: 711.59284 | T3: 744.58058 | U3: 100
C4: 120 | D4: 373.2328 | E4: 396.79548 | F4: 419.41565 | G4: 450.51838 | H4: 473.13855 | I4: 495.75872 | J4: 523.09142 | K4: 547.59661 | L4: 574.92931 | M4: 604 | O4: 623.93968 | P4: 649.38737 | Q4: 673.89255 | R4: 703.11027 | S4: 725.73044 | T4: 754.94816 | U4: 120
C5: 140 | D5: 379.83035 | E5: 407.16305 | F5: 425.07069 | G5: 459.00094 | H5: 481.62111 | I5: 508.01131 | J5: 530.63148 | K5: 554.19416 | L5: 587.1819 | M5: 612 | O5: 634.30726 | P5: 657.86993 | Q5: 684.26013 | R5: 711.59284 | S5: 737.98303 | T5: 763.43073 | U5: 140
C6: 160 | D6: 396.79548 | E6: 421.30066 | F6: 459.00094 | G6: 479.7361 | H6: 506.1263 | I6: 535.34402 | J6: 557.96418 | K6: 590.95193 | L6: 613.5721 | M6: 647 | O6: 670.12253 | P6: 694.62771 | Q6: 725.73044 | R6: 754.94816 | S6: 777.56833 | T6: 810.55608 | U6: 160
C7: 180 | D7: 410.93308 | E7: 442.03582 | F7: 473.13855 | G7: 502.35627 | H7: 524.97644 | I7: 551.36664 | J7: 587.1819 | K7: 611.68709 | L7: 640.90481 | M7: 670 | O7: 699.34025 | P7: 727.61546 | Q7: 758.71819 | R7: 786.0509 | S7: 815.26861 | T7: 839.7738 | U7: 180
C8: 200 | D8: 421.30066 | E8: 459.00094 | F8: 485.39114 | G8: 514.60886 | H8: 543.82658 | I8: 574.92931 | J8: 606.03205 | K8: 634.30726 | L8: 668.23751 | M8: 691 | O8: 723.84543 | P8: 753.06315 | Q8: 777.56833 | R8: 813.3836 | S8: 837.88878 | T8: 872.76155 | U8: 200
C9: 220 | D9: 459.00094 | E9: 485.39114 | F9: 520.2639 | G9: 549.48162 | H9: 587.1819 | I9: 616.39962 | J9: 649.38737 | K9: 684.26013 | L9: 711.59284 | M9: 753 | O9: 779.45335 | P9: 815.26861 | Q9: 848.25636 | R9: 881.24411 | S9: 0 | T9: 0 | U9: 220
C10: 240 | D10: 462.77097 | E10: 491.98869 | F10: 524.97644 | G10: 557.96418 | H10: 595.66447 | I10: 628.65221 | J10: 657.86993 | K10: 694.62771 | L10: 727.61546 | M10: 763 | O10: 794.53346 | P10: 827.52121 | Q10: 0 | R10: 0 | S10: 0 | T10: 0 | U10: 240
C11: 260 | D11: 487.27615 | E11: 523.09142 | F11: 557.96418 | G11: 603.20452 | H11: 634.30726 | I11: 670.12253 | J11: 706.8803 | K11: 748.35061 | L11: 777.56833 | M11: 819 | O11: 854.85391 | P11: 0 | Q11: 0 | R11: 0 | S11: 0 | T11: 0 | U11: 260
C12: 280 | D12: 495.75872 | E12: 535.34402 | F12: 568.33176 | G12: 609.80207 | H12: 647.50236 | I12: 682.37512 | J12: 715.36287 | K12: 756.83318 | L12: 792.64844 | M12: 828 | O12: 0 | P12: 0 | Q12: 0 | R12: 0 | S12: 0 | T12: 0 | U12: 280
C14: H B | D14: 100 | E14: 120 | F14: 140 | G14: 160 | H14: 180 | I14: 200 | J14: 220 | K14: 240 | L14: 260 | M14: 280 | O14: 300 | P14: 320 | Q14: 340 | R14: 360 | S14: 380 | T14: 400
C15: 100 | D15: 557.96418 | E15: 590.95193 | F15: 609.80207 | G15: 637.13478 | H15: 661.63996 | I15: 688.97267 | J15: 711.59284 | K15: 744.58058 | L15: 763.43073 | M15: 788 | O15: 815.26861 | P15: 836.00377 | Q15: 868.99152 | R15: 889.72667 | S15: 914.23186 | T15: 939.67955 | U15: 100
C16: 120 | D16: 572.10179 | E16: 597.54948 | F16: 620.16965 | G16: 649.38737 | H16: 672.00754 | I16: 694.62771 | J16: 717.24788 | K16: 751.17813 | L16: 773.7983 | M16: 801 | O16: 820.92366 | P16: 848.25636 | Q16: 875.58907 | R16: 903.86428 | S16: 922.71442 | T16: 951.93214 | U16: 120
C17: 140 | D17: 576.81433 | E17: 607.91706 | F17: 628.65221 | G17: 653.1574 | H17: 682.37512 | I17: 706.8803 | J17: 732.32799 | K17: 756.83318 | L17: 786.0509 | M17: 813 | O17: 834.11876 | P17: 858.62394 | Q17: 881.24411 | R17: 914.23186 | S17: 934.96701 | T17: 962.29972 | U17: 140
C18: 160 | D18: 597.54948 | E18: 623.93968 | F18: 653.1574 | G18: 675.77757 | H18: 704.99529 | I18: 737.98303 | J18: 758.71819 | K18: 787.93591 | L18: 815.26861 | M18: 842 | O18: 870.87653 | P18: 896.32422 | Q18: 922.71442 | R18: 951.93214 | S18: 979.26484 | T18: 1010.3676 | U18: 160
C19: 180 | D19: 611.68709 | E19: 640.90481 | F19: 672.00754 | G19: 699.34025 | H19: 723.84543 | I19: 754.94816 | J19: 786.0509 | K19: 813.3836 | L19: 837.88878 | M19: 871 | O19: 900.09425 | P19: 929.31197 | Q19: 960.4147 | R19: 983.03487 | S19: 1016.0226 | T19: 1043.3553 | U19: 180
C20: 200 | D20: 623.93968 | E20: 653.1574 | F20: 686.14515 | G20: 711.59284 | H20: 746.4656 | I20: 773.7983 | J20: 803.01602 | K20: 834.11876 | L20: 868.99152 | M20: 892 | O20: 920.82941 | P20: 950.04713 | Q20: 979.26484 | R20: 1012.2526 | S20: 1040.5278 | T20: 1074.4581 | U20: 200
C21: 220 | D21: 653.1574 | E21: 686.14515 | F21: 715.36287 | G21: 753.06315 | H21: 786.0509 | I21: 817.15363 | J21: 848.25636 | K21: 881.24411 | L21: 914.23186 | M21: 950 | O21: 981.14986 | P21: 1016.0226 | Q21: 1047.1254 | R21: 1081.9981 | S21: 0 | T21: 0 | U21: 220
C22: 240 | D22: 657.86993 | E22: 692.7427 | F22: 723.84543 | G22: 758.71819 | H22: 794.53346 | I22: 827.52121 | J22: 858.62394 | K22: 896.32422 | L22: 929.31197 | M22: 962 | O22: 991.51744 | P22: 1032.9877 | Q22: 0 | R22: 0 | S22: 0 | T22: 0 | U22: 240
C23: 260 | D23: 688.97267 | E23: 717.24788 | F23: 758.71819 | G23: 800.1885 | H23: 834.11876 | I23: 870.87653 | J23: 910.46183 | K23: 943.44958 | L23: 979.26484 | M23: 1020 | O23: 1055.6079 | P23: 0 | Q23: 0 | R23: 0 | S23: 0 | T23: 0 | U23: 260
C24: 280 | D24: 694.62771 | E24: 737.98303 | F24: 769.08577 | G24: 810.55608 | H24: 841.65881 | I24: 879.3591 | J24: 917.05938 | K24: 953.81715 | L24: 989.63242 | M24: 1033 | O24: 0 | P24: 0 | Q24: 0 | R24: 0 | S24: 0 | T24: 0 | U24: 280
D26: Meerprijs Trend / RAL kleuren
C27: B | D27: 100 | E27: 120 | F27: 140 | G27: 160 | H27: 180 | I27: 200 | J27: 220 | K27: 240 | L27: 260 | M27: 280 | O27: 300 | P27: 320 | Q27: 340 | R27: 360 | S27: 380 | T27: 400
C28: RAL | D28: 203.58153 | E28: 203.58153 | F28: 203.58153 | G28: 203.58153 | H28: 203.58153 | I28: 262.01697 | J28: 262.01697 | K28: 262.01697 | L28: 262.01697 | M28: 262.02 | O28: 319.5099 | P28: 319.5099 | Q28: 319.5099 | R28: 319.5099 | S28: 319.5099 | T28: 377.94533
C29: Trend | D29: 101.79076 | E29: 101.79076 | F29: 101.79076 | G29: 101.79076 | H29: 101.79076 | I29: 131.00848 | J29: 131.00848 | K29: 131.00848 | L29: 131.00848 | M29: 131.01 | O29: 159.75495 | P29: 159.75495 | Q29: 159.75495 | R29: 159.75495 | S29: 159.75495 | T29: 188.97267
A31: Let op: vanaf hoogte 230 cm is kast 100 nodig.
A32: Veelgekozen opties
A33: Solar uitvoering incl. 1-kanaals handzender op Carré 100 | L33: 274
A34: LT 50 32 rpm (meerprijs t.o.v. motor) | L34: 90
A35: Sunilus io 17 rpm (meerprijs t.o.v. motor) | L35: 182.5
A36: Maestria io 32 rpm (meerprijs t.o.v. motor) | L36: 197
A37: Sunfix systeem draaistangbediening | L37: 62
A38: Sunfix elektrisch (inclusief Maestria io) | L38: 274
A39: Situo 1 io handzender | L39: 70
A40: Minderprijs bandbediening (t.o.v. tabel draaistangbediening) -/- | L40: -57

Sheet 70 (2)
A1: Square 70
A2: Motor (Screenjob LS40) Draaistangbediening | B2: H B | C2: 100 | D2: 120 | E2: 140 | F2: 160 | G2: 180 | H2: 200 | I2: 220 | J2: 240
B3: 100 | C3: 319.5099 | D3: 338.36004 | E3: 362.86522 | F3: 383.60038 | G3: 404.33553 | H3: 421.30066 | I3: 448.63336 | J3: 469 | L3: 100
B4: 120 | C4: 327.99246 | D4: 348.72762 | E4: 371.34779 | F4: 390.19793 | G4: 410.93308 | H4: 427.89821 | I4: 459.00094 | J4: 477 | L4: 120
B5: 140 | C5: 338.36004 | D5: 359.09519 | E5: 379.83035 | F5: 396.79548 | G5: 417.53063 | H5: 445.80584 | I5: 464.65598 | J5: 486 | L5: 140
B6: 160 | C6: 352.49764 | D6: 373.2328 | E6: 396.79548 | F6: 419.41565 | G6: 448.63336 | H6: 469.36852 | I6: 490.10368 | J6: 515 | L6: 160
B7: 180 | C7: 365.69274 | D7: 392.08294 | E7: 414.70311 | F7: 445.80584 | G7: 469.36852 | H7: 490.10368 | I7: 514.60886 | J7: 544 | L7: 180
B8: 200 | C8: 383.60038 | D8: 407.16305 | E8: 427.89821 | F8: 462.77097 | G8: 485.39114 | H8: 512.72385 | I8: 540.99906 | J8: 560 | L8: 200
B9: 220 | C9: 407.16305 | D9: 440.1508 | E9: 469.36852 | F9: 495.75872 | G9: 524.97644 | H9: 551.36664 | I9: 587.1819 | L9: 220
B10: 240 | C10: 410.93308 | D10: 448.63336 | E10: 476.90858 | F10: 504.24128 | G10: 535.34402 | H10: 559.8492 | I10: 0 | L10: 240
B12: H B | C12: 100 | D12: 120 | E12: 140 | F12: 160 | G12: 180 | H12: 200 | I12: 220 | J12: 240
B13: 100 | C13: 520.2639 | D13: 537.22903 | E13: 559.8492 | F13: 585.29689 | G13: 606.03205 | H13: 623.93968 | I13: 647.50236 | J13: 668 | L13: 100
B14: 120 | C14: 528.74647 | D14: 547.59661 | E14: 568.33176 | F14: 592.83695 | G14: 611.68709 | H14: 632.42224 | I14: 653.1574 | J14: 674 | L14: 120
B15: 140 | C15: 537.22903 | D15: 554.19416 | E15: 576.81433 | F15: 597.54948 | G15: 616.39962 | H15: 644.67484 | I15: 661.63996 | J15: 687 | L15: 140
B16: 160 | C16: 549.48162 | D16: 572.10179 | E16: 597.54948 | F16: 620.16965 | G16: 647.50236 | H16: 668.23751 | I16: 690.85768 | J16: 711 | L16: 160
B17: 180 | C17: 561.73421 | D17: 595.66447 | E17: 613.5721 | F17: 644.67484 | G17: 668.23751 | H17: 690.85768 | I17: 711.59284 | J17: 747 | L17: 180
B18: 200 | C18: 585.29689 | D18: 607.91706 | E18: 632.42224 | F18: 657.86993 | G18: 686.14515 | H18: 709.70782 | I18: 744.58058 | J18: 763 | L18: 200
C20: Meerprijs Trend / RAL kleuren
B21: B | C21: 100 | D21: 120 | E21: 140 | F21: 160 | G21: 180 | H21: 200 | I21: 220 | J21: 240
B22: RAL | C22: 204 | D22: 204 | E22: 204 | F22: 204 | G22: 204 | H22: 262 | I22: 262 | J22: 262
B23: Trend | C23: 102 | D23: 102 | E23: 102 | F23: 102 | G23: 102 | H23: 131 | I23: 131 | J23: 131
K24: 76
A25: Veelgekozen opties
A27: Sunea io 40 16 rpm (meerprijs t.o.v. motor) | H27: 188
A28: Situo 1 io handzender | H28: 70
A29: Sunfix systeem draaistangbediening | H29: 62
A30: Sunfix elektrisch inclusief Sunfix schakelaar | H30: 219
A31: Minderprijs bandbediening (t.o.v. tabel draaistangbediening) -/- | H31: -57

Sheet 85&100
A1: Square 85/100 Carré 85/100 (alleen elektrisch)
A2: Motor (LT50 12 RPM) Draaistangbediening | C2: H B | D2: 100 | E2: 120 | F2: 140 | G2: 160 | H2: 180 | I2: 200 | J2: 220 | K2: 240 | L2: 260 | M2: 280 | N2: 300 | O2: 320 | P2: 340 | Q2: 360 | R2: 380 | S2: 400
C3: 100 | D3: =(('85&100 (2)'!D3/(1+Korting!$B$3)*(1-Korting!$B$2)*Prijsmutaties!$B$9)) -> 350.61009 | E3: =(('85&100 (2)'!E3/(1+Korting!$B$3)*(1-Korting!$B$2)*Prijsmutaties!$B$9)) -> 377.15759 | F3: =(('85&100 (2)'!F3/(1+Korting!$B$3)*(1-Korting!$B$2)*Prijsmutaties!$B$9)) -> 397.29707 | G3: =(('85&100 (2)'!G3/(1+Korting!$B$3)*(1-Korting!$B$2)*Prijsmutaties!$B$9)) -> 427.50629 | H3: =(('85&100 (2)'!H3/(1+Korting!$B$3)*(1-Korting!$B$2)*Prijsmutaties!$B$9)) -> 451.3075 | I3: =(('85&100 (2)'!I3/(1+Korting!$B$3)*(1-Korting!$B$2)*Prijsmutaties!$B$9)) -> 473.27785 | J3: =(('85&100 (2)'!J3/(1+Korting!$B$3)*(1-Korting!$B$2)*Prijsmutaties!$B$9)) -> 499.82535 | K3: =(('85&100 (2)'!K3/(1+Korting!$B$3)*(1-Korting!$B$2)*Prijsmutaties!$B$9)) -> 525.45742 | ... M3: =(('85&100 (2)'!M3/(1+Korting!$B$3)*(1-Korting!$B$2)*Prijsmutaties!$B$9)) -> 574.02195 | N3: =(('85&100 (2)'!O3/(1+Korting!$B$3)*(1-Korting!$B$2)*Prijsmutaties!$B$9)) -> 595.94561 | O3: =(('85&100 (2)'!P3/(1+Korting!$B$3)*(1-Korting!$B$2)*Prijsmutaties!$B$9)) -> 618.83138 | P3: =(('85&100 (2)'!Q3/(1+Korting!$B$3)*(1-Korting!$B$2)*Prijsmutaties!$B$9)) -> 649.04061 | Q3: =(('85&100 (2)'!R3/(1+Korting!$B$3)*(1-Korting!$B$2)*Prijsmutaties!$B$9)) -> 669.18009 | R3: =(('85&100 (2)'!S3/(1+Korting!$B$3)*(1-Korting!$B$2)*Prijsmutaties!$B$9)) -> 691.15043 | S3: =(('85&100 (2)'!T3/(1+Korting!$B$3)*(1-Korting!$B$2)*Prijsmutaties!$B$9)) -> 723.19052 | T3: 100
C4: 120 | D4: =(('85&100 (2)'!D4/(1+Korting!$B$3)*(1-Korting!$B$2)*Prijsmutaties!$B$9)) -> 362.51069 | E4: =(('85&100 (2)'!E4/(1+Korting!$B$3)*(1-Korting!$B$2)*Prijsmutaties!$B$9)) -> 385.39647 | F4: =(('85&100 (2)'!F4/(1+Korting!$B$3)*(1-Korting!$B$2)*Prijsmutaties!$B$9)) -> 407.36681 | G4: =(('85&100 (2)'!G4/(1+Korting!$B$3)*(1-Korting!$B$2)*Prijsmutaties!$B$9)) -> 437.57604 | H4: =(('85&100 (2)'!H4/(1+Korting!$B$3)*(1-Korting!$B$2)*Prijsmutaties!$B$9)) -> 459.54638 | I4: =(('85&100 (2)'!I4/(1+Korting!$B$3)*(1-Korting!$B$2)*Prijsmutaties!$B$9)) -> 481.51673 | J4: =(('85&100 (2)'!J4/(1+Korting!$B$3)*(1-Korting!$B$2)*Prijsmutaties!$B$9)) -> 508.06423 | K4: =(('85&100 (2)'!K4/(1+Korting!$B$3)*(1-Korting!$B$2)*Prijsmutaties!$B$9)) -> 531.86543 | ... M4: =(('85&100 (2)'!M4/(1+Korting!$B$3)*(1-Korting!$B$2)*Prijsmutaties!$B$9)) -> 586.64849 | N4: =(('85&100 (2)'!O4/(1+Korting!$B$3)*(1-Korting!$B$2)*Prijsmutaties!$B$9)) -> 606.01535 | O4: =(('85&100 (2)'!P4/(1+Korting!$B$3)*(1-Korting!$B$2)*Prijsmutaties!$B$9)) -> 630.73198 | P4: =(('85&100 (2)'!Q4/(1+Korting!$B$3)*(1-Korting!$B$2)*Prijsmutaties!$B$9)) -> 654.53319 | Q4: =(('85&100 (2)'!R4/(1+Korting!$B$3)*(1-Korting!$B$2)*Prijsmutaties!$B$9)) -> 682.91155 | R4: =(('85&100 (2)'!S4/(1+Korting!$B$3)*(1-Korting!$B$2)*Prijsmutaties!$B$9)) -> 704.8819 | S4: =(('85&100 (2)'!T4/(1+Korting!$B$3)*(1-Korting!$B$2)*Prijsmutaties!$B$9)) -> 733.26026 | T4: 120
C5: 140 | D5: =(('85&100 (2)'!D5/(1+Korting!$B$3)*(1-Korting!$B$2)*Prijsmutaties!$B$9)) -> 368.91871 | E5: =(('85&100 (2)'!E5/(1+Korting!$B$3)*(1-Korting!$B$2)*Prijsmutaties!$B$9)) -> 395.46621 | F5: =(('85&100 (2)'!F5/(1+Korting!$B$3)*(1-Korting!$B$2)*Prijsmutaties!$B$9)) -> 412.8594 | G5: =(('85&100 (2)'!G5/(1+Korting!$B$3)*(1-Korting!$B$2)*Prijsmutaties!$B$9)) -> 445.81492 | H5: =(('85&100 (2)'!H5/(1+Korting!$B$3)*(1-Korting!$B$2)*Prijsmutaties!$B$9)) -> 467.78526 | I5: =(('85&100 (2)'!I5/(1+Korting!$B$3)*(1-Korting!$B$2)*Prijsmutaties!$B$9)) -> 493.41733 | J5: =(('85&100 (2)'!J5/(1+Korting!$B$3)*(1-Korting!$B$2)*Prijsmutaties!$B$9)) -> 515.38767 | K5: =(('85&100 (2)'!K5/(1+Korting!$B$3)*(1-Korting!$B$2)*Prijsmutaties!$B$9)) -> 538.27345 | ... M5: =(('85&100 (2)'!M5/(1+Korting!$B$3)*(1-Korting!$B$2)*Prijsmutaties!$B$9)) -> 594.41867 | N5: =(('85&100 (2)'!O5/(1+Korting!$B$3)*(1-Korting!$B$2)*Prijsmutaties!$B$9)) -> 616.08509 | O5: =(('85&100 (2)'!P5/(1+Korting!$B$3)*(1-Korting!$B$2)*Prijsmutaties!$B$9)) -> 638.97086 | P5: =(('85&100 (2)'!Q5/(1+Korting!$B$3)*(1-Korting!$B$2)*Prijsmutaties!$B$9)) -> 664.60293 | Q5: =(('85&100 (2)'!R5/(1+Korting!$B$3)*(1-Korting!$B$2)*Prijsmutaties!$B$9)) -> 691.15043 | R5: =(('85&100 (2)'!S5/(1+Korting!$B$3)*(1-Korting!$B$2)*Prijsmutaties!$B$9)) -> 716.7825 | S5: =(('85&100 (2)'!T5/(1+Korting!$B$3)*(1-Korting!$B$2)*Prijsmutaties!$B$9)) -> 741.49914 | T5: 140
C6: 160 | D6: =(('85&100 (2)'!D6/(1+Korting!$B$3)*(1-Korting!$B$2)*Prijsmutaties!$B$9)) -> 385.39647 | E6: =(('85&100 (2)'!E6/(1+Korting!$B$3)*(1-Korting!$B$2)*Prijsmutaties!$B$9)) -> 409.19767 | F6: =(('85&100 (2)'!F6/(1+Korting!$B$3)*(1-Korting!$B$2)*Prijsmutaties!$B$9)) -> 445.81492 | G6: =(('85&100 (2)'!G6/(1+Korting!$B$3)*(1-Korting!$B$2)*Prijsmutaties!$B$9)) -> 465.9544 | H6: =(('85&100 (2)'!H6/(1+Korting!$B$3)*(1-Korting!$B$2)*Prijsmutaties!$B$9)) -> 491.58647 | I6: =(('85&100 (2)'!I6/(1+Korting!$B$3)*(1-Korting!$B$2)*Prijsmutaties!$B$9)) -> 519.96483 | J6: =(('85&100 (2)'!J6/(1+Korting!$B$3)*(1-Korting!$B$2)*Prijsmutaties!$B$9)) -> 541.93517 | K6: =(('85&100 (2)'!K6/(1+Korting!$B$3)*(1-Korting!$B$2)*Prijsmutaties!$B$9)) -> 573.97526 | ... M6: =(('85&100 (2)'!M6/(1+Korting!$B$3)*(1-Korting!$B$2)*Prijsmutaties!$B$9)) -> 628.4132 | N6: =(('85&100 (2)'!O6/(1+Korting!$B$3)*(1-Korting!$B$2)*Prijsmutaties!$B$9)) -> 650.87147 | O6: =(('85&100 (2)'!P6/(1+Korting!$B$3)*(1-Korting!$B$2)*Prijsmutaties!$B$9)) -> 674.67267 | P6: =(('85&100 (2)'!Q6/(1+Korting!$B$3)*(1-Korting!$B$2)*Prijsmutaties!$B$9)) -> 704.8819 | Q6: =(('85&100 (2)'!R6/(1+Korting!$B$3)*(1-Korting!$B$2)*Prijsmutaties!$B$9)) -> 733.26026 | R6: =(('85&100 (2)'!S6/(1+Korting!$B$3)*(1-Korting!$B$2)*Prijsmutaties!$B$9)) -> 755.23061 | S6: =(('85&100 (2)'!T6/(1+Korting!$B$3)*(1-Korting!$B$2)*Prijsmutaties!$B$9)) -> 787.27069 | T6: 160
C7: 180 | D7: =(('85&100 (2)'!D7/(1+Korting!$B$3)*(1-Korting!$B$2)*Prijsmutaties!$B$9)) -> 399.12793 | E7: =(('85&100 (2)'!E7/(1+Korting!$B$3)*(1-Korting!$B$2)*Prijsmutaties!$B$9)) -> 429.33716 | F7: =(('85&100 (2)'!F7/(1+Korting!$B$3)*(1-Korting!$B$2)*Prijsmutaties!$B$9)) -> 459.54638 | G7: =(('85&100 (2)'!G7/(1+Korting!$B$3)*(1-Korting!$B$2)*Prijsmutaties!$B$9)) -> 487.92474 | H7: =(('85&100 (2)'!H7/(1+Korting!$B$3)*(1-Korting!$B$2)*Prijsmutaties!$B$9)) -> 509.89509 | I7: =(('85&100 (2)'!I7/(1+Korting!$B$3)*(1-Korting!$B$2)*Prijsmutaties!$B$9)) -> 535.52716 | J7: =(('85&100 (2)'!J7/(1+Korting!$B$3)*(1-Korting!$B$2)*Prijsmutaties!$B$9)) -> 570.31354 | K7: =(('85&100 (2)'!K7/(1+Korting!$B$3)*(1-Korting!$B$2)*Prijsmutaties!$B$9)) -> 594.11474 | ... M7: =(('85&100 (2)'!M7/(1+Korting!$B$3)*(1-Korting!$B$2)*Prijsmutaties!$B$9)) -> 650.75246 | N7: =(('85&100 (2)'!O7/(1+Korting!$B$3)*(1-Korting!$B$2)*Prijsmutaties!$B$9)) -> 679.24983 | O7: =(('85&100 (2)'!P7/(1+Korting!$B$3)*(1-Korting!$B$2)*Prijsmutaties!$B$9)) -> 706.71276 | P7: =(('85&100 (2)'!Q7/(1+Korting!$B$3)*(1-Korting!$B$2)*Prijsmutaties!$B$9)) -> 736.92199 | Q7: =(('85&100 (2)'!R7/(1+Korting!$B$3)*(1-Korting!$B$2)*Prijsmutaties!$B$9)) -> 763.46949 | R7: =(('85&100 (2)'!S7/(1+Korting!$B$3)*(1-Korting!$B$2)*Prijsmutaties!$B$9)) -> 791.84785 | S7: =(('85&100 (2)'!T7/(1+Korting!$B$3)*(1-Korting!$B$2)*Prijsmutaties!$B$9)) -> 815.64905 | T7: 180
C8: 200 | D8: =(('85&100 (2)'!D8/(1+Korting!$B$3)*(1-Korting!$B$2)*Prijsmutaties!$B$9)) -> 409.19767 | E8: =(('85&100 (2)'!E8/(1+Korting!$B$3)*(1-Korting!$B$2)*Prijsmutaties!$B$9)) -> 445.81492 | F8: =(('85&100 (2)'!F8/(1+Korting!$B$3)*(1-Korting!$B$2)*Prijsmutaties!$B$9)) -> 471.44698 | G8: =(('85&100 (2)'!G8/(1+Korting!$B$3)*(1-Korting!$B$2)*Prijsmutaties!$B$9)) -> 499.82535 | H8: =(('85&100 (2)'!H8/(1+Korting!$B$3)*(1-Korting!$B$2)*Prijsmutaties!$B$9)) -> 528.20371 | I8: =(('85&100 (2)'!I8/(1+Korting!$B$3)*(1-Korting!$B$2)*Prijsmutaties!$B$9)) -> 558.41293 | J8: =(('85&100 (2)'!J8/(1+Korting!$B$3)*(1-Korting!$B$2)*Prijsmutaties!$B$9)) -> 588.62216 | K8: =(('85&100 (2)'!K8/(1+Korting!$B$3)*(1-Korting!$B$2)*Prijsmutaties!$B$9)) -> 616.08509 | ... M8: =(('85&100 (2)'!M8/(1+Korting!$B$3)*(1-Korting!$B$2)*Prijsmutaties!$B$9)) -> 671.14918 | N8: =(('85&100 (2)'!O8/(1+Korting!$B$3)*(1-Korting!$B$2)*Prijsmutaties!$B$9)) -> 703.05104 | O8: =(('85&100 (2)'!P8/(1+Korting!$B$3)*(1-Korting!$B$2)*Prijsmutaties!$B$9)) -> 731.4294 | P8: =(('85&100 (2)'!Q8/(1+Korting!$B$3)*(1-Korting!$B$2)*Prijsmutaties!$B$9)) -> 755.23061 | Q8: =(('85&100 (2)'!R8/(1+Korting!$B$3)*(1-Korting!$B$2)*Prijsmutaties!$B$9)) -> 790.01699 | R8: =(('85&100 (2)'!S8/(1+Korting!$B$3)*(1-Korting!$B$2)*Prijsmutaties!$B$9)) -> 813.81819 | S8: =(('85&100 (2)'!T8/(1+Korting!$B$3)*(1-Korting!$B$2)*Prijsmutaties!$B$9)) -> 847.68914 | T8: 200
C9: 220 | D9: =(('85&100 (2)'!D9/(1+Korting!$B$3)*(1-Korting!$B$2)*Prijsmutaties!$B$9)) -> 445.81492 | E9: =(('85&100 (2)'!E9/(1+Korting!$B$3)*(1-Korting!$B$2)*Prijsmutaties!$B$9)) -> 471.44698 | F9: =(('85&100 (2)'!F9/(1+Korting!$B$3)*(1-Korting!$B$2)*Prijsmutaties!$B$9)) -> 505.31793 | G9: =(('85&100 (2)'!G9/(1+Korting!$B$3)*(1-Korting!$B$2)*Prijsmutaties!$B$9)) -> 533.69629 | H9: =(('85&100 (2)'!H9/(1+Korting!$B$3)*(1-Korting!$B$2)*Prijsmutaties!$B$9)) -> 570.31354 | I9: =(('85&100 (2)'!I9/(1+Korting!$B$3)*(1-Korting!$B$2)*Prijsmutaties!$B$9)) -> 598.6919 | J9: =(('85&100 (2)'!J9/(1+Korting!$B$3)*(1-Korting!$B$2)*Prijsmutaties!$B$9)) -> 630.73198 | K9: =(('85&100 (2)'!K9/(1+Korting!$B$3)*(1-Korting!$B$2)*Prijsmutaties!$B$9)) -> 664.60293 | ... M9: =(('85&100 (2)'!M9/(1+Korting!$B$3)*(1-Korting!$B$2)*Prijsmutaties!$B$9)) -> 731.36806 | N9: =(('85&100 (2)'!O9/(1+Korting!$B$3)*(1-Korting!$B$2)*Prijsmutaties!$B$9)) -> 757.06147 | O9: =(('85&100 (2)'!P9/(1+Korting!$B$3)*(1-Korting!$B$2)*Prijsmutaties!$B$9)) -> 791.84785 | P9: =(('85&100 (2)'!Q9/(1+Korting!$B$3)*(1-Korting!$B$2)*Prijsmutaties!$B$9)) -> 823.88793 | Q9: =(('85&100 (2)'!R9/(1+Korting!$B$3)*(1-Korting!$B$2)*Prijsmutaties!$B$9)) -> 855.92802 | T9: 220
C10: 240 | D10: =(('85&100 (2)'!D10/(1+Korting!$B$3)*(1-Korting!$B$2)*Prijsmutaties!$B$9)) -> 449.47664 | E10: =(('85&100 (2)'!E10/(1+Korting!$B$3)*(1-Korting!$B$2)*Prijsmutaties!$B$9)) -> 477.855 | F10: =(('85&100 (2)'!F10/(1+Korting!$B$3)*(1-Korting!$B$2)*Prijsmutaties!$B$9)) -> 509.89509 | G10: =(('85&100 (2)'!G10/(1+Korting!$B$3)*(1-Korting!$B$2)*Prijsmutaties!$B$9)) -> 541.93517 | H10: =(('85&100 (2)'!H10/(1+Korting!$B$3)*(1-Korting!$B$2)*Prijsmutaties!$B$9)) -> 578.55242 | I10: =(('85&100 (2)'!I10/(1+Korting!$B$3)*(1-Korting!$B$2)*Prijsmutaties!$B$9)) -> 610.5925 | J10: =(('85&100 (2)'!J10/(1+Korting!$B$3)*(1-Korting!$B$2)*Prijsmutaties!$B$9)) -> 638.97086 | K10: =(('85&100 (2)'!K10/(1+Korting!$B$3)*(1-Korting!$B$2)*Prijsmutaties!$B$9)) -> 674.67267 | ... M10: =(('85&100 (2)'!M10/(1+Korting!$B$3)*(1-Korting!$B$2)*Prijsmutaties!$B$9)) -> 741.08079 | N10: =(('85&100 (2)'!O10/(1+Korting!$B$3)*(1-Korting!$B$2)*Prijsmutaties!$B$9)) -> 771.70836 | O10: =(('85&100 (2)'!P10/(1+Korting!$B$3)*(1-Korting!$B$2)*Prijsmutaties!$B$9)) -> 803.74845 | T10: 240
C11: 260 | D11: =(('85&100 (2)'!D11/(1+Korting!$B$3)*(1-Korting!$B$2)*Prijsmutaties!$B$9)) -> 473.27785 | E11: =(('85&100 (2)'!E11/(1+Korting!$B$3)*(1-Korting!$B$2)*Prijsmutaties!$B$9)) -> 508.06423 | F11: =(('85&100 (2)'!F11/(1+Korting!$B$3)*(1-Korting!$B$2)*Prijsmutaties!$B$9)) -> 541.93517 | G11: =(('85&100 (2)'!G11/(1+Korting!$B$3)*(1-Korting!$B$2)*Prijsmutaties!$B$9)) -> 585.87586 | H11: =(('85&100 (2)'!H11/(1+Korting!$B$3)*(1-Korting!$B$2)*Prijsmutaties!$B$9)) -> 616.08509 | I11: =(('85&100 (2)'!I11/(1+Korting!$B$3)*(1-Korting!$B$2)*Prijsmutaties!$B$9)) -> 650.87147 | J11: =(('85&100 (2)'!J11/(1+Korting!$B$3)*(1-Korting!$B$2)*Prijsmutaties!$B$9)) -> 686.57328 | K11: =(('85&100 (2)'!K11/(1+Korting!$B$3)*(1-Korting!$B$2)*Prijsmutaties!$B$9)) -> 726.85224 | ... M11: =(('85&100 (2)'!M11/(1+Korting!$B$3)*(1-Korting!$B$2)*Prijsmutaties!$B$9)) -> 795.47204 | N11: =(('85&100 (2)'!O11/(1+Korting!$B$3)*(1-Korting!$B$2)*Prijsmutaties!$B$9)) -> 830.29595 | T11: 260
C12: 280 | D12: =(('85&100 (2)'!D12/(1+Korting!$B$3)*(1-Korting!$B$2)*Prijsmutaties!$B$9)) -> 481.51673 | E12: =(('85&100 (2)'!E12/(1+Korting!$B$3)*(1-Korting!$B$2)*Prijsmutaties!$B$9)) -> 519.96483 | F12: =(('85&100 (2)'!F12/(1+Korting!$B$3)*(1-Korting!$B$2)*Prijsmutaties!$B$9)) -> 552.00492 | G12: =(('85&100 (2)'!G12/(1+Korting!$B$3)*(1-Korting!$B$2)*Prijsmutaties!$B$9)) -> 592.28388 | H12: =(('85&100 (2)'!H12/(1+Korting!$B$3)*(1-Korting!$B$2)*Prijsmutaties!$B$9)) -> 628.90112 | I12: =(('85&100 (2)'!I12/(1+Korting!$B$3)*(1-Korting!$B$2)*Prijsmutaties!$B$9)) -> 662.77207 | J12: =(('85&100 (2)'!J12/(1+Korting!$B$3)*(1-Korting!$B$2)*Prijsmutaties!$B$9)) -> 694.81216 | K12: =(('85&100 (2)'!K12/(1+Korting!$B$3)*(1-Korting!$B$2)*Prijsmutaties!$B$9)) -> 735.09112 | ... M12: =(('85&100 (2)'!M12/(1+Korting!$B$3)*(1-Korting!$B$2)*Prijsmutaties!$B$9)) -> 804.21349 | T12: 280
C14: H B | D14: 100 | E14: 120 | F14: 140 | G14: 160 | H14: 180 | I14: 200 | J14: 220 | K14: 240 | L14: 260 | M14: 280 | N14: 300 | O14: 320 | P14: 340 | Q14: 360 | R14: 380 | S14: 400
C15: 100 | D15: =(('85&100 (2)'!D15/(1+Korting!$B$3)*(1-Korting!$B$2)*Prijsmutaties!$B$9)) -> 541.93517 | E15: =(('85&100 (2)'!E15/(1+Korting!$B$3)*(1-Korting!$B$2)*Prijsmutaties!$B$9)) -> 573.97526 | F15: =(('85&100 (2)'!F15/(1+Korting!$B$3)*(1-Korting!$B$2)*Prijsmutaties!$B$9)) -> 592.28388 | G15: =(('85&100 (2)'!G15/(1+Korting!$B$3)*(1-Korting!$B$2)*Prijsmutaties!$B$9)) -> 618.83138 | H15: =(('85&100 (2)'!H15/(1+Korting!$B$3)*(1-Korting!$B$2)*Prijsmutaties!$B$9)) -> 642.63259 | I15: =(('85&100 (2)'!I15/(1+Korting!$B$3)*(1-Korting!$B$2)*Prijsmutaties!$B$9)) -> 669.18009 | J15: =(('85&100 (2)'!J15/(1+Korting!$B$3)*(1-Korting!$B$2)*Prijsmutaties!$B$9)) -> 691.15043 | K15: =(('85&100 (2)'!K15/(1+Korting!$B$3)*(1-Korting!$B$2)*Prijsmutaties!$B$9)) -> 723.19052 | ... M15: =(('85&100 (2)'!M15/(1+Korting!$B$3)*(1-Korting!$B$2)*Prijsmutaties!$B$9)) -> 765.3626 | N15: =(('85&100 (2)'!O15/(1+Korting!$B$3)*(1-Korting!$B$2)*Prijsmutaties!$B$9)) -> 791.84785 | O15: =(('85&100 (2)'!P15/(1+Korting!$B$3)*(1-Korting!$B$2)*Prijsmutaties!$B$9)) -> 811.98733 | P15: =(('85&100 (2)'!Q15/(1+Korting!$B$3)*(1-Korting!$B$2)*Prijsmutaties!$B$9)) -> 844.02742 | Q15: =(('85&100 (2)'!R15/(1+Korting!$B$3)*(1-Korting!$B$2)*Prijsmutaties!$B$9)) -> 864.1669 | R15: =(('85&100 (2)'!S15/(1+Korting!$B$3)*(1-Korting!$B$2)*Prijsmutaties!$B$9)) -> 887.96811 | S15: =(('85&100 (2)'!T15/(1+Korting!$B$3)*(1-Korting!$B$2)*Prijsmutaties!$B$9)) -> 912.68474 | T15: 100
C16: 120 | D16: =(('85&100 (2)'!D16/(1+Korting!$B$3)*(1-Korting!$B$2)*Prijsmutaties!$B$9)) -> 555.66664 | E16: =(('85&100 (2)'!E16/(1+Korting!$B$3)*(1-Korting!$B$2)*Prijsmutaties!$B$9)) -> 580.38328 | F16: =(('85&100 (2)'!F16/(1+Korting!$B$3)*(1-Korting!$B$2)*Prijsmutaties!$B$9)) -> 602.35362 | G16: =(('85&100 (2)'!G16/(1+Korting!$B$3)*(1-Korting!$B$2)*Prijsmutaties!$B$9)) -> 630.73198 | H16: =(('85&100 (2)'!H16/(1+Korting!$B$3)*(1-Korting!$B$2)*Prijsmutaties!$B$9)) -> 652.70233 | I16: =(('85&100 (2)'!I16/(1+Korting!$B$3)*(1-Korting!$B$2)*Prijsmutaties!$B$9)) -> 674.67267 | J16: =(('85&100 (2)'!J16/(1+Korting!$B$3)*(1-Korting!$B$2)*Prijsmutaties!$B$9)) -> 696.64302 | K16: =(('85&100 (2)'!K16/(1+Korting!$B$3)*(1-Korting!$B$2)*Prijsmutaties!$B$9)) -> 729.59854 | ... M16: =(('85&100 (2)'!M16/(1+Korting!$B$3)*(1-Korting!$B$2)*Prijsmutaties!$B$9)) -> 777.98914 | N16: =(('85&100 (2)'!O16/(1+Korting!$B$3)*(1-Korting!$B$2)*Prijsmutaties!$B$9)) -> 797.34043 | O16: =(('85&100 (2)'!P16/(1+Korting!$B$3)*(1-Korting!$B$2)*Prijsmutaties!$B$9)) -> 823.88793 | P16: =(('85&100 (2)'!Q16/(1+Korting!$B$3)*(1-Korting!$B$2)*Prijsmutaties!$B$9)) -> 850.43543 | Q16: =(('85&100 (2)'!R16/(1+Korting!$B$3)*(1-Korting!$B$2)*Prijsmutaties!$B$9)) -> 877.89836 | R16: =(('85&100 (2)'!S16/(1+Korting!$B$3)*(1-Korting!$B$2)*Prijsmutaties!$B$9)) -> 896.20699 | S16: =(('85&100 (2)'!T16/(1+Korting!$B$3)*(1-Korting!$B$2)*Prijsmutaties!$B$9)) -> 924.58535 | T16: 120
C17: 140 | D17: =(('85&100 (2)'!D17/(1+Korting!$B$3)*(1-Korting!$B$2)*Prijsmutaties!$B$9)) -> 560.24379 | E17: =(('85&100 (2)'!E17/(1+Korting!$B$3)*(1-Korting!$B$2)*Prijsmutaties!$B$9)) -> 590.45302 | F17: =(('85&100 (2)'!F17/(1+Korting!$B$3)*(1-Korting!$B$2)*Prijsmutaties!$B$9)) -> 610.5925 | G17: =(('85&100 (2)'!G17/(1+Korting!$B$3)*(1-Korting!$B$2)*Prijsmutaties!$B$9)) -> 634.39371 | H17: =(('85&100 (2)'!H17/(1+Korting!$B$3)*(1-Korting!$B$2)*Prijsmutaties!$B$9)) -> 662.77207 | I17: =(('85&100 (2)'!I17/(1+Korting!$B$3)*(1-Korting!$B$2)*Prijsmutaties!$B$9)) -> 686.57328 | J17: =(('85&100 (2)'!J17/(1+Korting!$B$3)*(1-Korting!$B$2)*Prijsmutaties!$B$9)) -> 711.28992 | K17: =(('85&100 (2)'!K17/(1+Korting!$B$3)*(1-Korting!$B$2)*Prijsmutaties!$B$9)) -> 735.09112 | ... M17: =(('85&100 (2)'!M17/(1+Korting!$B$3)*(1-Korting!$B$2)*Prijsmutaties!$B$9)) -> 789.6444 | N17: =(('85&100 (2)'!O17/(1+Korting!$B$3)*(1-Korting!$B$2)*Prijsmutaties!$B$9)) -> 810.15647 | O17: =(('85&100 (2)'!P17/(1+Korting!$B$3)*(1-Korting!$B$2)*Prijsmutaties!$B$9)) -> 833.95767 | P17: =(('85&100 (2)'!Q17/(1+Korting!$B$3)*(1-Korting!$B$2)*Prijsmutaties!$B$9)) -> 855.92802 | Q17: =(('85&100 (2)'!R17/(1+Korting!$B$3)*(1-Korting!$B$2)*Prijsmutaties!$B$9)) -> 887.96811 | R17: =(('85&100 (2)'!S17/(1+Korting!$B$3)*(1-Korting!$B$2)*Prijsmutaties!$B$9)) -> 908.10759 | S17: =(('85&100 (2)'!T17/(1+Korting!$B$3)*(1-Korting!$B$2)*Prijsmutaties!$B$9)) -> 934.65509 | T17: 140
C18: 160 | D18: =(('85&100 (2)'!D18/(1+Korting!$B$3)*(1-Korting!$B$2)*Prijsmutaties!$B$9)) -> 580.38328 | E18: =(('85&100 (2)'!E18/(1+Korting!$B$3)*(1-Korting!$B$2)*Prijsmutaties!$B$9)) -> 606.01535 | F18: =(('85&100 (2)'!F18/(1+Korting!$B$3)*(1-Korting!$B$2)*Prijsmutaties!$B$9)) -> 634.39371 | G18: =(('85&100 (2)'!G18/(1+Korting!$B$3)*(1-Korting!$B$2)*Prijsmutaties!$B$9)) -> 656.36405 | H18: =(('85&100 (2)'!H18/(1+Korting!$B$3)*(1-Korting!$B$2)*Prijsmutaties!$B$9)) -> 684.74242 | I18: =(('85&100 (2)'!I18/(1+Korting!$B$3)*(1-Korting!$B$2)*Prijsmutaties!$B$9)) -> 716.7825 | J18: =(('85&100 (2)'!J18/(1+Korting!$B$3)*(1-Korting!$B$2)*Prijsmutaties!$B$9)) -> 736.92199 | K18: =(('85&100 (2)'!K18/(1+Korting!$B$3)*(1-Korting!$B$2)*Prijsmutaties!$B$9)) -> 765.30035 | ... M18: =(('85&100 (2)'!M18/(1+Korting!$B$3)*(1-Korting!$B$2)*Prijsmutaties!$B$9)) -> 817.8113 | N18: =(('85&100 (2)'!O18/(1+Korting!$B$3)*(1-Korting!$B$2)*Prijsmutaties!$B$9)) -> 845.85828 | O18: =(('85&100 (2)'!P18/(1+Korting!$B$3)*(1-Korting!$B$2)*Prijsmutaties!$B$9)) -> 870.57492 | P18: =(('85&100 (2)'!Q18/(1+Korting!$B$3)*(1-Korting!$B$2)*Prijsmutaties!$B$9)) -> 896.20699 | Q18: =(('85&100 (2)'!R18/(1+Korting!$B$3)*(1-Korting!$B$2)*Prijsmutaties!$B$9)) -> 924.58535 | R18: =(('85&100 (2)'!S18/(1+Korting!$B$3)*(1-Korting!$B$2)*Prijsmutaties!$B$9)) -> 951.13285 | S18: =(('85&100 (2)'!T18/(1+Korting!$B$3)*(1-Korting!$B$2)*Prijsmutaties!$B$9)) -> 981.34207 | T18: 160
C19: 180 | D19: =(('85&100 (2)'!D19/(1+Korting!$B$3)*(1-Korting!$B$2)*Prijsmutaties!$B$9)) -> 594.11474 | E19: =(('85&100 (2)'!E19/(1+Korting!$B$3)*(1-Korting!$B$2)*Prijsmutaties!$B$9)) -> 622.49311 | F19: =(('85&100 (2)'!F19/(1+Korting!$B$3)*(1-Korting!$B$2)*Prijsmutaties!$B$9)) -> 652.70233 | G19: =(('85&100 (2)'!G19/(1+Korting!$B$3)*(1-Korting!$B$2)*Prijsmutaties!$B$9)) -> 679.24983 | H19: =(('85&100 (2)'!H19/(1+Korting!$B$3)*(1-Korting!$B$2)*Prijsmutaties!$B$9)) -> 703.05104 | I19: =(('85&100 (2)'!I19/(1+Korting!$B$3)*(1-Korting!$B$2)*Prijsmutaties!$B$9)) -> 733.26026 | J19: =(('85&100 (2)'!J19/(1+Korting!$B$3)*(1-Korting!$B$2)*Prijsmutaties!$B$9)) -> 763.46949 | K19: =(('85&100 (2)'!K19/(1+Korting!$B$3)*(1-Korting!$B$2)*Prijsmutaties!$B$9)) -> 790.01699 | ... M19: =(('85&100 (2)'!M19/(1+Korting!$B$3)*(1-Korting!$B$2)*Prijsmutaties!$B$9)) -> 845.9782 | N19: =(('85&100 (2)'!O19/(1+Korting!$B$3)*(1-Korting!$B$2)*Prijsmutaties!$B$9)) -> 874.23664 | O19: =(('85&100 (2)'!P19/(1+Korting!$B$3)*(1-Korting!$B$2)*Prijsmutaties!$B$9)) -> 902.615 | P19: =(('85&100 (2)'!Q19/(1+Korting!$B$3)*(1-Korting!$B$2)*Prijsmutaties!$B$9)) -> 932.82423 | Q19: =(('85&100 (2)'!R19/(1+Korting!$B$3)*(1-Korting!$B$2)*Prijsmutaties!$B$9)) -> 954.79457 | R19: =(('85&100 (2)'!S19/(1+Korting!$B$3)*(1-Korting!$B$2)*Prijsmutaties!$B$9)) -> 986.83466 | S19: =(('85&100 (2)'!T19/(1+Korting!$B$3)*(1-Korting!$B$2)*Prijsmutaties!$B$9)) -> 1013.3822 | T19: 180
C20: 200 | D20: =(('85&100 (2)'!D20/(1+Korting!$B$3)*(1-Korting!$B$2)*Prijsmutaties!$B$9)) -> 606.01535 | E20: =(('85&100 (2)'!E20/(1+Korting!$B$3)*(1-Korting!$B$2)*Prijsmutaties!$B$9)) -> 634.39371 | F20: =(('85&100 (2)'!F20/(1+Korting!$B$3)*(1-Korting!$B$2)*Prijsmutaties!$B$9)) -> 666.4338 | G20: =(('85&100 (2)'!G20/(1+Korting!$B$3)*(1-Korting!$B$2)*Prijsmutaties!$B$9)) -> 691.15043 | H20: =(('85&100 (2)'!H20/(1+Korting!$B$3)*(1-Korting!$B$2)*Prijsmutaties!$B$9)) -> 725.02138 | I20: =(('85&100 (2)'!I20/(1+Korting!$B$3)*(1-Korting!$B$2)*Prijsmutaties!$B$9)) -> 751.56888 | J20: =(('85&100 (2)'!J20/(1+Korting!$B$3)*(1-Korting!$B$2)*Prijsmutaties!$B$9)) -> 779.94724 | K20: =(('85&100 (2)'!K20/(1+Korting!$B$3)*(1-Korting!$B$2)*Prijsmutaties!$B$9)) -> 810.15647 | ... M20: =(('85&100 (2)'!M20/(1+Korting!$B$3)*(1-Korting!$B$2)*Prijsmutaties!$B$9)) -> 866.37492 | N20: =(('85&100 (2)'!O20/(1+Korting!$B$3)*(1-Korting!$B$2)*Prijsmutaties!$B$9)) -> 894.37612 | O20: =(('85&100 (2)'!P20/(1+Korting!$B$3)*(1-Korting!$B$2)*Prijsmutaties!$B$9)) -> 922.75449 | P20: =(('85&100 (2)'!Q20/(1+Korting!$B$3)*(1-Korting!$B$2)*Prijsmutaties!$B$9)) -> 951.13285 | Q20: =(('85&100 (2)'!R20/(1+Korting!$B$3)*(1-Korting!$B$2)*Prijsmutaties!$B$9)) -> 983.17293 | R20: =(('85&100 (2)'!S20/(1+Korting!$B$3)*(1-Korting!$B$2)*Prijsmutaties!$B$9)) -> 1010.6359 | S20: =(('85&100 (2)'!T20/(1+Korting!$B$3)*(1-Korting!$B$2)*Prijsmutaties!$B$9)) -> 1043.5914 | T20: 200
C21: 220 | D21: =(('85&100 (2)'!D21/(1+Korting!$B$3)*(1-Korting!$B$2)*Prijsmutaties!$B$9)) -> 634.39371 | E21: =(('85&100 (2)'!E21/(1+Korting!$B$3)*(1-Korting!$B$2)*Prijsmutaties!$B$9)) -> 666.4338 | F21: =(('85&100 (2)'!F21/(1+Korting!$B$3)*(1-Korting!$B$2)*Prijsmutaties!$B$9)) -> 694.81216 | G21: =(('85&100 (2)'!G21/(1+Korting!$B$3)*(1-Korting!$B$2)*Prijsmutaties!$B$9)) -> 731.4294 | H21: =(('85&100 (2)'!H21/(1+Korting!$B$3)*(1-Korting!$B$2)*Prijsmutaties!$B$9)) -> 763.46949 | I21: =(('85&100 (2)'!I21/(1+Korting!$B$3)*(1-Korting!$B$2)*Prijsmutaties!$B$9)) -> 793.67871 | J21: =(('85&100 (2)'!J21/(1+Korting!$B$3)*(1-Korting!$B$2)*Prijsmutaties!$B$9)) -> 823.88793 | K21: =(('85&100 (2)'!K21/(1+Korting!$B$3)*(1-Korting!$B$2)*Prijsmutaties!$B$9)) -> 855.92802 | ... M21: =(('85&100 (2)'!M21/(1+Korting!$B$3)*(1-Korting!$B$2)*Prijsmutaties!$B$9)) -> 922.70871 | N21: =(('85&100 (2)'!O21/(1+Korting!$B$3)*(1-Korting!$B$2)*Prijsmutaties!$B$9)) -> 952.96371 | O21: =(('85&100 (2)'!P21/(1+Korting!$B$3)*(1-Korting!$B$2)*Prijsmutaties!$B$9)) -> 986.83466 | P21: =(('85&100 (2)'!Q21/(1+Korting!$B$3)*(1-Korting!$B$2)*Prijsmutaties!$B$9)) -> 1017.0439 | Q21: =(('85&100 (2)'!R21/(1+Korting!$B$3)*(1-Korting!$B$2)*Prijsmutaties!$B$9)) -> 1050.9148 | T21: 220
C22: 240 | D22: =(('85&100 (2)'!D22/(1+Korting!$B$3)*(1-Korting!$B$2)*Prijsmutaties!$B$9)) -> 638.97086 | E22: =(('85&100 (2)'!E22/(1+Korting!$B$3)*(1-Korting!$B$2)*Prijsmutaties!$B$9)) -> 672.84181 | F22: =(('85&100 (2)'!F22/(1+Korting!$B$3)*(1-Korting!$B$2)*Prijsmutaties!$B$9)) -> 703.05104 | G22: =(('85&100 (2)'!G22/(1+Korting!$B$3)*(1-Korting!$B$2)*Prijsmutaties!$B$9)) -> 736.92199 | H22: =(('85&100 (2)'!H22/(1+Korting!$B$3)*(1-Korting!$B$2)*Prijsmutaties!$B$9)) -> 771.70836 | I22: =(('85&100 (2)'!I22/(1+Korting!$B$3)*(1-Korting!$B$2)*Prijsmutaties!$B$9)) -> 803.74845 | J22: =(('85&100 (2)'!J22/(1+Korting!$B$3)*(1-Korting!$B$2)*Prijsmutaties!$B$9)) -> 833.95767 | K22: =(('85&100 (2)'!K22/(1+Korting!$B$3)*(1-Korting!$B$2)*Prijsmutaties!$B$9)) -> 870.57492 | ... M22: =(('85&100 (2)'!M22/(1+Korting!$B$3)*(1-Korting!$B$2)*Prijsmutaties!$B$9)) -> 934.36398 | N22: =(('85&100 (2)'!O22/(1+Korting!$B$3)*(1-Korting!$B$2)*Prijsmutaties!$B$9)) -> 963.03345 | O22: =(('85&100 (2)'!P22/(1+Korting!$B$3)*(1-Korting!$B$2)*Prijsmutaties!$B$9)) -> 1003.3124 | T22: 240
C23: 260 | D23: =(('85&100 (2)'!D23/(1+Korting!$B$3)*(1-Korting!$B$2)*Prijsmutaties!$B$9)) -> 669.18009 | E23: =(('85&100 (2)'!E23/(1+Korting!$B$3)*(1-Korting!$B$2)*Prijsmutaties!$B$9)) -> 696.64302 | F23: =(('85&100 (2)'!F23/(1+Korting!$B$3)*(1-Korting!$B$2)*Prijsmutaties!$B$9)) -> 736.92199 | G23: =(('85&100 (2)'!G23/(1+Korting!$B$3)*(1-Korting!$B$2)*Prijsmutaties!$B$9)) -> 777.20095 | H23: =(('85&100 (2)'!H23/(1+Korting!$B$3)*(1-Korting!$B$2)*Prijsmutaties!$B$9)) -> 810.15647 | I23: =(('85&100 (2)'!I23/(1+Korting!$B$3)*(1-Korting!$B$2)*Prijsmutaties!$B$9)) -> 845.85828 | J23: =(('85&100 (2)'!J23/(1+Korting!$B$3)*(1-Korting!$B$2)*Prijsmutaties!$B$9)) -> 884.30638 | K23: =(('85&100 (2)'!K23/(1+Korting!$B$3)*(1-Korting!$B$2)*Prijsmutaties!$B$9)) -> 916.34647 | ... M23: =(('85&100 (2)'!M23/(1+Korting!$B$3)*(1-Korting!$B$2)*Prijsmutaties!$B$9)) -> 990.69778 | N23: =(('85&100 (2)'!O23/(1+Korting!$B$3)*(1-Korting!$B$2)*Prijsmutaties!$B$9)) -> 1025.2828 | T23: 260
C24: 280 | D24: =(('85&100 (2)'!D24/(1+Korting!$B$3)*(1-Korting!$B$2)*Prijsmutaties!$B$9)) -> 674.67267 | E24: =(('85&100 (2)'!E24/(1+Korting!$B$3)*(1-Korting!$B$2)*Prijsmutaties!$B$9)) -> 716.7825 | F24: =(('85&100 (2)'!F24/(1+Korting!$B$3)*(1-Korting!$B$2)*Prijsmutaties!$B$9)) -> 746.99173 | G24: =(('85&100 (2)'!G24/(1+Korting!$B$3)*(1-Korting!$B$2)*Prijsmutaties!$B$9)) -> 787.27069 | H24: =(('85&100 (2)'!H24/(1+Korting!$B$3)*(1-Korting!$B$2)*Prijsmutaties!$B$9)) -> 817.47992 | I24: =(('85&100 (2)'!I24/(1+Korting!$B$3)*(1-Korting!$B$2)*Prijsmutaties!$B$9)) -> 854.09716 | J24: =(('85&100 (2)'!J24/(1+Korting!$B$3)*(1-Korting!$B$2)*Prijsmutaties!$B$9)) -> 890.7144 | K24: =(('85&100 (2)'!K24/(1+Korting!$B$3)*(1-Korting!$B$2)*Prijsmutaties!$B$9)) -> 926.41621 | ... M24: =(('85&100 (2)'!M24/(1+Korting!$B$3)*(1-Korting!$B$2)*Prijsmutaties!$B$9)) -> 1003.3243 | T24: 280
D26: Meerprijs Trend / RAL kleuren
C27: B | D27: 100 | E27: 120 | F27: 140 | G27: 160 | H27: 180 | I27: 200 | J27: 220 | K27: 240 | L27: 260 | M27: 280 | N27: 300 | O27: 320 | P27: 340 | Q27: 360 | R27: 380 | S27: 400
C28: RAL | D28: =(('85&100 (2)'!D28/(1+Korting!$B$3)*(1-Korting!$B$2)*Prijsmutaties!$B$9)) -> 197.7331 | E28: =(('85&100 (2)'!E28/(1+Korting!$B$3)*(1-Korting!$B$2)*Prijsmutaties!$B$9)) -> 197.7331 | F28: =(('85&100 (2)'!F28/(1+Korting!$B$3)*(1-Korting!$B$2)*Prijsmutaties!$B$9)) -> 197.7331 | G28: =(('85&100 (2)'!G28/(1+Korting!$B$3)*(1-Korting!$B$2)*Prijsmutaties!$B$9)) -> 197.7331 | H28: =(('85&100 (2)'!H28/(1+Korting!$B$3)*(1-Korting!$B$2)*Prijsmutaties!$B$9)) -> 197.7331 | I28: =(('85&100 (2)'!I28/(1+Korting!$B$3)*(1-Korting!$B$2)*Prijsmutaties!$B$9)) -> 254.48983 | J28: =(('85&100 (2)'!J28/(1+Korting!$B$3)*(1-Korting!$B$2)*Prijsmutaties!$B$9)) -> 254.48983 | K28: =(('85&100 (2)'!K28/(1+Korting!$B$3)*(1-Korting!$B$2)*Prijsmutaties!$B$9)) -> 254.48983 | ... M28: =(('85&100 (2)'!M28/(1+Korting!$B$3)*(1-Korting!$B$2)*Prijsmutaties!$B$9)) -> 254.49278 | N28: =(('85&100 (2)'!O28/(1+Korting!$B$3)*(1-Korting!$B$2)*Prijsmutaties!$B$9)) -> 310.33112 | O28: =(('85&100 (2)'!P28/(1+Korting!$B$3)*(1-Korting!$B$2)*Prijsmutaties!$B$9)) -> 310.33112 | P28: =(('85&100 (2)'!Q28/(1+Korting!$B$3)*(1-Korting!$B$2)*Prijsmutaties!$B$9)) -> 310.33112 | Q28: =(('85&100 (2)'!R28/(1+Korting!$B$3)*(1-Korting!$B$2)*Prijsmutaties!$B$9)) -> 310.33112 | R28: =(('85&100 (2)'!S28/(1+Korting!$B$3)*(1-Korting!$B$2)*Prijsmutaties!$B$9)) -> 310.33112 | S28: =(('85&100 (2)'!T28/(1+Korting!$B$3)*(1-Korting!$B$2)*Prijsmutaties!$B$9)) -> 367.08785
C29: Trend | D29: =(('85&100 (2)'!D29/(1+Korting!$B$3)*(1-Korting!$B$2)*Prijsmutaties!$B$9)) -> 98.866552 | E29: =(('85&100 (2)'!E29/(1+Korting!$B$3)*(1-Korting!$B$2)*Prijsmutaties!$B$9)) -> 98.866552 | F29: =(('85&100 (2)'!F29/(1+Korting!$B$3)*(1-Korting!$B$2)*Prijsmutaties!$B$9)) -> 98.866552 | G29: =(('85&100 (2)'!G29/(1+Korting!$B$3)*(1-Korting!$B$2)*Prijsmutaties!$B$9)) -> 98.866552 | H29: =(('85&100 (2)'!H29/(1+Korting!$B$3)*(1-Korting!$B$2)*Prijsmutaties!$B$9)) -> 98.866552 | I29: =(('85&100 (2)'!I29/(1+Korting!$B$3)*(1-Korting!$B$2)*Prijsmutaties!$B$9)) -> 127.24491 | J29: =(('85&100 (2)'!J29/(1+Korting!$B$3)*(1-Korting!$B$2)*Prijsmutaties!$B$9)) -> 127.24491 | K29: =(('85&100 (2)'!K29/(1+Korting!$B$3)*(1-Korting!$B$2)*Prijsmutaties!$B$9)) -> 127.24491 | ... M29: =(('85&100 (2)'!M29/(1+Korting!$B$3)*(1-Korting!$B$2)*Prijsmutaties!$B$9)) -> 127.24639 | N29: =(('85&100 (2)'!O29/(1+Korting!$B$3)*(1-Korting!$B$2)*Prijsmutaties!$B$9)) -> 155.16556 | O29: =(('85&100 (2)'!P29/(1+Korting!$B$3)*(1-Korting!$B$2)*Prijsmutaties!$B$9)) -> 155.16556 | P29: =(('85&100 (2)'!Q29/(1+Korting!$B$3)*(1-Korting!$B$2)*Prijsmutaties!$B$9)) -> 155.16556 | Q29: =(('85&100 (2)'!R29/(1+Korting!$B$3)*(1-Korting!$B$2)*Prijsmutaties!$B$9)) -> 155.16556 | R29: =(('85&100 (2)'!S29/(1+Korting!$B$3)*(1-Korting!$B$2)*Prijsmutaties!$B$9)) -> 155.16556 | S29: =(('85&100 (2)'!T29/(1+Korting!$B$3)*(1-Korting!$B$2)*Prijsmutaties!$B$9)) -> 183.54392
C31: Let op: Hoger dan 220 cm, automatisch kast 100
A33: Veelgekozen opties
A34: Solar uitvoering Brel incl. 1-kanaals handzender op Carré 100 | L34: =(('85&100 (2)'!L33/(1+Korting!$B$3)*(1-Korting!$B$2)*Prijsmutaties!$G$9)) -> 246.97001 | M34: =(('85&100 (2)'!M33/(1+Korting!$B$3)*(1-Korting!$B$2))) -> 0
A35: LT 50 32 rpm (meerprijs t.o.v. motor) | L35: =(('85&100 (2)'!L34/(1+Korting!$B$3)*(1-Korting!$B$2)*Prijsmutaties!$G$9)) -> 81.121537 | M35: =(('85&100 (2)'!M34/(1+Korting!$B$3)*(1-Korting!$B$2))) -> 0
A36: Sunilus io 17 rpm (meerprijs t.o.v. motor) | L36: =(('85&100 (2)'!L35/(1+Korting!$B$3)*(1-Korting!$B$2)*Prijsmutaties!$G$9)) -> 164.49645 | M36: =(('85&100 (2)'!M35/(1+Korting!$B$3)*(1-Korting!$B$2))) -> 0
A37: Maestria io 32 rpm (meerprijs t.o.v. motor) | L37: =(('85&100 (2)'!L36/(1+Korting!$B$3)*(1-Korting!$B$2)*Prijsmutaties!$G$9)) -> 177.56603 | M37: =(('85&100 (2)'!M36/(1+Korting!$B$3)*(1-Korting!$B$2))) -> 0
A38: Sunfix systeem draaistangbediening | L38: =(('85&100 (2)'!L37/(1+Korting!$B$3)*(1-Korting!$B$2)*Prijsmutaties!$G$9)) -> 55.883726 | M38: =(('85&100 (2)'!M37/(1+Korting!$B$3)*(1-Korting!$B$2))) -> 0
A39: Sunfix elektrisch (inclusief Maestria io) | L39: =(('85&100 (2)'!L38/(1+Korting!$B$3)*(1-Korting!$B$2)*Prijsmutaties!$G$9)) -> 246.97001 | M39: =(('85&100 (2)'!M38/(1+Korting!$B$3)*(1-Korting!$B$2))) -> 0
A40: Situo 1 io handzender | L40: =(('85&100 (2)'!L39/(1+Korting!$B$3)*(1-Korting!$B$2)*Prijsmutaties!$G$9)) -> 63.094529 | M40: =(('85&100 (2)'!M39/(1+Korting!$B$3)*(1-Korting!$B$2))) -> 0
A41: Minderprijs bandbediening* (t.o.v. tabel draaistangbediening) -/- | L41: =(('85&100 (2)'!L40/(1+Korting!$B$3)*(1-Korting!$B$2)*Prijsmutaties!$G$9)) -> -51.376974 | M41: =(('85&100 (2)'!M40/(1+Korting!$B$3)*(1-Korting!$B$2))) -> 0
C42: * Max. H = 250 cm / B = 340 cm / 6m2

Sheet Zip 85&100 (2)
A1: Zip Square 85/100 (Sunilus io 17 rpm) Zip Carré 85/100 (Sunilus io 17 rpm)
A2: Motor (Sunilus io 17 rpm) | C2: H B | D2: 100 | E2: 120 | F2: 140 | G2: 160 | H2: 180 | I2: 200 | J2: 220 | K2: 240 | L2: 260 | M2: 280 | N2: 300 | O2: 320 | P2: 340 | Q2: 360 | R2: 380 | S2: 400
C3: 100 | D3: 830.34873 | E3: 855.79642 | F3: 880.3016 | G3: 907.63431 | H3: 942.50707 | I3: 963.24222 | J3: 995.28746 | K3: 1021.6777 | L3: 1050.8954 | M3: 1073.5156 | N3: 1107.4458 | O3: 1131.951 | P3: 1163.0537 | Q3: 1186.6164 | R3: 1217.7191 | S3: 1240.3393 | T3: 100
C4: 120 | D4: 861.45146 | E4: 892.55419 | F4: 918.00189 | G4: 950.98963 | H4: 980.20735 | I4: 1011.3101 | J4: 1045.2403 | K4: 1071.6305 | L4: 1105.5608 | M4: 1131.951 | N4: 1167.7663 | O4: 1188.5014 | P4: 1226.2017 | Q4: 1252.5919 | R4: 1286.5221 | S4: 1312.9123 | T4: 120
C5: 140 | D5: 890.66918 | E5: 928.36946 | F5: 959.4722 | G5: 990.57493 | H5: 1024.5052 | I5: 1055.6079 | J5: 1090.4807 | K5: 1126.2959 | L5: 1155.5137 | M5: 1190.3864 | N5: 1221.4892 | O5: 1257.3044 | P5: 1288.4072 | Q5: 1317.6249 | R5: 1354.3827 | S5: 1383.6004 | T5: 140
C6: 160 | D6: 924.59943 | E6: 966.06975 | F6: 999.05749 | G6: 1030.1602 | H6: 1069.7455 | I6: 1100.8483 | J6: 1136.6635 | K6: 1173.4213 | L6: 1211.1216 | M6: 1242.2243 | N6: 1281.8096 | O6: 1312.9123 | P6: 1346.8426 | Q6: 1386.4279 | R6: 1421.3007 | S6: 1450.5184 | T6: 160
C7: 180 | D7: 961.35721 | E7: 1000.9425 | F7: 1032.0452 | G7: 1073.5156 | H7: 1115.9284 | I7: 1148.9161 | J7: 1183.7889 | K7: 1226.2017 | L7: 1259.1894 | M7: 1298.7747 | N7: 1336.475 | O7: 1376.0603 | P7: 1409.0481 | Q7: 1448.6334 | R7: 1483.5061 | S7: 1524.9764 | T7: 180
C8: 200 | D8: 995.28746 | E8: 1034.8728 | F8: 1080.1131 | G8: 1119.6984 | H8: 1157.3987 | I8: 1195.099 | J8: 1240.3393 | K8: 1279.9246 | L8: 1317.6249 | M8: 1359.0952 | N8: 1404.3355 | O8: 1440.1508 | P8: 1481.6211 | Q8: 1521.2064 | R8: 1560.7917 | S8: 1600.377 | T8: 200
C9: 220 | D9: 1024.5052 | E9: 1071.6305 | F9: 1113.1008 | G9: 1150.8011 | H9: 1196.984 | I9: 1240.3393 | J9: 1279.9246 | K9: 1321.3949 | L9: 1367.5778 | M9: 1409.0481 | N9: 1446.7484 | O9: 1488.2187 | P9: 1538.1715 | Q9: 1577.7568 | R9: 1619.2271 | S9: 1658.8124 | T9: 220
C10: 240 | D10: 1059.3779 | E10: 1105.5608 | F10: 1145.1461 | G10: 1190.3864 | H10: 1238.4543 | I10: 1283.6946 | J10: 1327.9925 | K10: 1373.2328 | L10: 1421.3007 | M10: 1464.656 | N10: 1510.8388 | O10: 1552.3091 | P10: 1593.7795 | Q10: 1639.9623 | R10: 1689.9152 | S10: 1735.1555 | T10: 240
C11: 260 | D11: 1092.3657 | E11: 1145.1461 | F11: 1190.3864 | G11: 1238.4543 | H11: 1286.5221 | I11: 1327.9925 | J11: 1377.9453 | K11: 1417.5306 | L11: 1459.0009 | M11: 1512.7238 | N11: 1560.7917 | O11: 1604.147 | P11: 1650.3299 | Q11: 1702.1678 | R11: 1750.2356 | S11: 1803.9585 | T11: 260
C12: 280 | D12: 1128.181 | E12: 1180.0189 | F12: 1228.0867 | G12: 1269.557 | H12: 1321.3949 | I12: 1373.2328 | J12: 1426.0132 | K12: 1452.4034 | L12: 1508.9538 | M12: 1552.3091 | N12: 1598.492 | O12: 1652.2149 | P12: 1702.1678 | Q12: 1748.3506 | R12: 1798.3035 | S12: 1848.2564 | T12: 280
C13: 300 | D13: 1148.9161 | E13: 1200.754 | F13: 1250.7069 | G13: 1298.7747 | H13: 1350.6126 | I13: 1402.4505 | J13: 1448.6334 | K13: 1479.7361 | L13: 1533.459 | M13: 1579.6418 | N13: 1631.4797 | O13: 1693.6852 | P13: 1735.1555 | Q13: 1783.2234 | R13: 1829.4062 | S13: 1885.0141 | T13: 300
C14: 320 | D14: 0 | E14: 0 | F14: 0 | G14: 1333.6475 | H14: 1388.3129 | I14: 1436.3808 | J14: 1481.6211 | K14: 1517.4364 | L14: 1567.3893 | M14: 1617.3421 | N14: 1662.5825 | O14: 1722.9029 | P14: 1769.0858 | Q14: 1822.8087 | R14: 1864.279 | S14: 0 | T14: 320
C15: 340 | D15: 0 | E15: 0 | F15: 0 | G15: 0 | H15: 0 | I15: 1475.0236 | J15: 1519.3214 | K15: 1550.4241 | L15: 1600.377 | M15: 1652.2149 | N15: 1702.1678 | O15: 1762.4882 | P15: 1805.8435 | Q15: 1858.6239 | R15: 0 | S15: 0 | T15: 340
D17: Meerprijs Trend / RAL kleuren
C18: B | D18: 100 | E18: 120 | F18: 140 | G18: 160 | H18: 180 | I18: 200 | J18: 220 | K18: 240 | L18: 260 | M18: 280 | N18: 300 | O18: 320 | P18: 340 | Q18: 360 | R18: 380 | S18: 400
C19: RAL | D19: 204.52403 | E19: 204.52403 | F19: 204.52403 | G19: 204.52403 | H19: 204.52403 | I19: 262.95947 | J19: 262.95947 | K19: 262.95947 | L19: 262.95947 | M19: 262.95947 | N19: 320.4524 | O19: 320.4524 | P19: 320.4524 | Q19: 320.4524 | R19: 320.4524 | S19: 378.88784
C20: Trend | D20: 102.26202 | E20: 102.26202 | F20: 102.26202 | G20: 102.26202 | H20: 102.26202 | I20: 131.47974 | J20: 131.47974 | K20: 131.47974 | L20: 131.47974 | M20: 131.47974 | N20: 160.2262 | O20: 160.2262 | P20: 160.2262 | Q20: 160.2262 | R20: 160.2262 | S20: 189.44392
A22: Let op: vanaf hoogte 200 cm is kast 100 nodig.
A23: Veelgekozen opties
A24: Solar uitvoering ZIP Carré 100 incl. 1-kanaals handzender | L24: 124
A25: Minderprijs LT 50 32 rpm | L25: -84
A26: Maestria io 32 rpm | L26: 45
A27: Situo 1 io handzender | L27: 70
A28: LHTF geleider per meter | L28: 14

Sheet Zip 85&100
A1: Zip Square 85/100 (Sunilus io 17 rpm) Zip Carré 85/100 (Sunilus io 17 rpm)
A2: Motor (Sunilus io 17 rpm) | B2: H B | C2: 100 | D2: 120 | E2: 140 | F2: 160 | G2: 180 | H2: 200 | I2: 220 | J2: 240 | K2: 260 | L2: 280 | M2: 300 | N2: 320 | O2: 340 | P2: 360 | Q2: 380 | R2: 400
B3: 100 | C3: =(('Zip 85&100 (2)'!D3/(1+Korting!$B$3)*(1-Korting!$B$2)*Prijsmutaties!$B$9)) -> 806.49474 | D3: =(('Zip 85&100 (2)'!E3/(1+Korting!$B$3)*(1-Korting!$B$2)*Prijsmutaties!$B$9)) -> 831.21138 | E3: =(('Zip 85&100 (2)'!F3/(1+Korting!$B$3)*(1-Korting!$B$2)*Prijsmutaties!$B$9)) -> 855.01259 | F3: =(('Zip 85&100 (2)'!G3/(1+Korting!$B$3)*(1-Korting!$B$2)*Prijsmutaties!$B$9)) -> 881.56009 | G3: =(('Zip 85&100 (2)'!H3/(1+Korting!$B$3)*(1-Korting!$B$2)*Prijsmutaties!$B$9)) -> 915.43104 | H3: =(('Zip 85&100 (2)'!I3/(1+Korting!$B$3)*(1-Korting!$B$2)*Prijsmutaties!$B$9)) -> 935.57052 | I3: =(('Zip 85&100 (2)'!J3/(1+Korting!$B$3)*(1-Korting!$B$2)*Prijsmutaties!$B$9)) -> 966.69518 | J3: =(('Zip 85&100 (2)'!K3/(1+Korting!$B$3)*(1-Korting!$B$2)*Prijsmutaties!$B$9)) -> 992.32724 | ... R3: =(('Zip 85&100 (2)'!S3/(1+Korting!$B$3)*(1-Korting!$B$2)*Prijsmutaties!$B$9)) -> 1204.7072 | S3: 100
